Workbook

Sheet RawData
A1: SN | B1: Time | C1: Program | D1: Station | E1: Column1 | F1: Channel | G1: Mode | H1: ---Times--- | I1: Temp Time | J1: Tx Test Time | K1: Rx Test Time | L1: Work Time | M1: Device | N1: ---Tx Test--- | O1: Start_WL(nm) | P1: WL(nm) | Q1: End_WL(nm) | R1: error_WL(nm) | S1: ndB_Width(nm) | T1: SMSR(dB) | U1: Sampling_Point | V1: Raw_Data | W1: DDMI_TxP | X1: ---Temp--- | Y1: Set_Temp | Z1: Case_Temp | AA1: DDMI_Temp | AB1: dTemp | AC1: LD_Temp | AD1: ---DUT--- | AE1: Ini_Bias(mA) | AF1: Set_Bias(mA) | AG1: DDMI_Bias(mA) | AH1: I2C_Vcc | AI1: DDMI_Vcc | AJ1: dVcc(%) | AK1: Programe_Version | AL1: --------- | AM1: ErrorCode
A2: 48226H40040 | B2: A2026100620533560886 | C2: TW-800G 2xFR4_TRx3T_TEC_OSA_Test.vi | D2: Temp | E2: 40 | F2: CH1 | G2: DUT 1 | I2: 186.49 | J2: 73.85 | L2: 268.04 | M2: Final test:T157100003549_1 | O2: 1260 | P2: 1271.6 | Q2: 1280 | R2: 0.6 | S2: 0.21 | T2: 52.72 | U2: 1001 | W2: -3.83 | Y2: 40 | Z2: 39.96 | AA2: 36.48 | AB2: 3.48 | AC2: 38.66 | AE2: 101 | AF2: 50 | AG2: 50 | AH2: 3.3 | AI2: 3.31 | AJ2: -0.01 | AK2: OSA_Test
A3: 48226H40040 | B3: A2026100620533560886 | C3: TW-800G 2xFR4_TRx3T_TEC_OSA_Test.vi | D3: Temp | E3: 40 | F3: CH2 | G3: DUT 1 | I3: 186.49 | J3: 73.85 | L3: 268.04 | M3: Final test:T157100003549_1 | O3: 1280 | P3: 1291.32 | Q3: 1300 | R3: 0.32 | S3: 0.22 | T3: 53.91 | U3: 1001 | W3: -2.74 | Y3: 40 | Z3: 39.96 | AA3: 36.48 | AB3: 3.48 | AC3: 38.22 | AE3: 83 | AF3: 50 | AG3: 50 | AH3: 3.3 | AI3: 3.31 | AJ3: -0.01 | AK3: OSA_Test
A4: 48226H40040 | B4: A2026100620533560886 | C4: TW-800G 2xFR4_TRx3T_TEC_OSA_Test.vi | D4: Temp | E4: 40 | F4: CH3 | G4: DUT 1 | I4: 186.49 | J4: 73.85 | L4: 268.04 | M4: Final test:T157100003549_1 | O4: 1300 | P4: 1311.76 | Q4: 1320 | R4: 0.76 | S4: 0.21 | T4: 49 | U4: 1001 | W4: -2.79 | Y4: 40 | Z4: 39.96 | AA4: 36.48 | AB4: 3.48 | AC4: 38.43 | AE4: 95 | AF4: 50 | AG4: 50 | AH4: 3.3 | AI4: 3.31 | AJ4: -0.01 | AK4: OSA_Test
A5: 48226H40040 | B5: A2026100620533560886 | C5: TW-800G 2xFR4_TRx3T_TEC_OSA_Test.vi | D5: Temp | E5: 40 | F5: CH4 | G5: DUT 1 | I5: 186.49 | J5: 73.85 | L5: 268.04 | M5: Final test:T157100003549_1 | O5: 1320 | P5: 1331.38 | Q5: 1340 | R5: 0.38 | S5: 0.2 | T5: 50.57 | U5: 1001 | W5: -3.08 | Y5: 40 | Z5: 39.96 | AA5: 36.48 | AB5: 3.48 | AC5: 38.43 | AE5: 114 | AF5: 50 | AG5: 50 | AH5: 3.3 | AI5: 3.31 | AJ5: -0.01 | AK5: OSA_Test
A6: 48226H40040 | B6: A2026100620533560886 | C6: TW-800G 2xFR4_TRx3T_TEC_OSA_Test.vi | D6: Temp | E6: 40 | F6: CH5 | G6: DUT 1 | I6: 186.49 | J6: 73.85 | L6: 268.04 | M6: Final test:T157100003549_1 | O6: 1260 | P6: 1271.6 | Q6: 1280 | R6: 0.6 | S6: 0.21 | T6: 52.72 | U6: 1001 | W6: -3.91 | Y6: 40 | Z6: 39.96 | AA6: 36.48 | AB6: 3.48 | AC6: 38.66 | AE6: 101 | AF6: 50 | AG6: 50 | AH6: 3.3 | AI6: 3.31 | AJ6: -0.01 | AK6: OSA_Test
A7: 48226H40040 | B7: A2026100620533560886 | C7: TW-800G 2xFR4_TRx3T_TEC_OSA_Test.vi | D7: Temp | E7: 40 | F7: CH6 | G7: DUT 1 | I7: 186.49 | J7: 73.85 | L7: 268.04 | M7: Final test:T157100003549_1 | O7: 1280 | P7: 1291.32 | Q7: 1300 | R7: 0.32 | S7: 0.22 | T7: 53.91 | U7: 1001 | W7: -2.45 | Y7: 40 | Z7: 39.96 | AA7: 36.48 | AB7: 3.48 | AC7: 38.22 | AE7: 83 | AF7: 50 | AG7: 50 | AH7: 3.3 | AI7: 3.31 | AJ7: -0.01 | AK7: OSA_Test
A8: 48226H40040 | B8: A2026100620533560886 | C8: TW-800G 2xFR4_TRx3T_TEC_OSA_Test.vi | D8: Temp | E8: 40 | F8: CH7 | G8: DUT 1 | I8: 186.49 | J8: 73.85 | L8: 268.04 | M8: Final test:T157100003549_1 | O8: 1300 | P8: 1311.76 | Q8: 1320 | R8: 0.76 | S8: 0.21 | T8: 49 | U8: 1001 | W8: -2.61 | Y8: 40 | Z8: 39.96 | AA8: 36.48 | AB8: 3.48 | AC8: 38.43 | AE8: 95 | AF8: 50 | AG8: 50 | AH8: 3.3 | AI8: 3.31 | AJ8: -0.01 | AK8: OSA_Test
A9: 48226H40040 | B9: A2026100620533560886 | C9: TW-800G 2xFR4_TRx3T_TEC_OSA_Test.vi | D9: Temp | E9: 40 | F9: CH8 | G9: DUT 1 | I9: 186.49 | J9: 73.85 | L9: 268.04 | M9: Final test:T157100003549_1 | O9: 1320 | P9: 1331.38 | Q9: 1340 | R9: 0.38 | S9: 0.2 | T9: 50.57 | U9: 1001 | W9: -3.7 | Y9: 40 | Z9: 39.96 | AA9: 36.48 | AB9: 3.48 | AC9: 38.43 | AE9: 114 | AF9: 50 | AG9: 50 | AH9: 3.3 | AI9: 3.31 | AJ9: -0.01 | AK9: OSA_Test
A10: 48226H40040 | B10: A2026100620533560886 | C10: TW-800G 2xFR4_TRx3T_TEC_OSA_Test.vi | D10: Temp | E10: 40 | F10: CH1 | G10: DUT 1 | J10: 74.17 | L10: 347.64 | O10: 1260 | P10: 1271.62 | Q10: 1280 | R10: 0.62 | S10: 0.21 | T10: 54.07 | U10: 1001 | W10: -2.27 | Z10: 39.96 | AA10: 36.73 | AB10: 3.23 | AC10: 38.98 | AF10: 60 | AG10: 60 | AH10: 3.3 | AI10: 3.3 | AJ10: 0
A11: 48226H40040 | B11: A2026100620533560886 | C11: TW-800G 2xFR4_TRx3T_TEC_OSA_Test.vi | D11: Temp | E11: 40 | F11: CH2 | G11: DUT 1 | J11: 74.17 | L11: 347.64 | O11: 1280 | P11: 1291.36 | Q11: 1300 | R11: 0.36 | S11: 0.21 | T11: 55 | U11: 1001 | W11: -0.63 | Z11: 39.96 | AA11: 36.73 | AB11: 3.23 | AC11: 38.59 | AF11: 60 | AG11: 60 | AH11: 3.3 | AI11: 3.3 | AJ11: 0
A12: 48226H40040 | B12: A2026100620533560886 | C12: TW-800G 2xFR4_TRx3T_TEC_OSA_Test.vi | D12: Temp | E12: 40 | F12: CH3 | G12: DUT 1 | J12: 74.17 | L12: 347.64 | O12: 1300 | P12: 1311.8 | Q12: 1320 | R12: 0.8 | S12: 0.21 | T12: 50.04 | U12: 1001 | W12: -1.51 | Z12: 39.96 | AA12: 36.73 | AB12: 3.23 | AC12: 38.74 | AF12: 60 | AG12: 60 | AH12: 3.3 | AI12: 3.3 | AJ12: 0
A13: 48226H40040 | B13: A2026100620533560886 | C13: TW-800G 2xFR4_TRx3T_TEC_OSA_Test.vi | D13: Temp | E13: 40 | F13: CH4 | G13: DUT 1 | J13: 74.17 | L13: 347.64 | O13: 1320 | P13: 1331.42 | Q13: 1340 | R13: 0.42 | S13: 0.2 | T13: 51.65 | U13: 1001 | W13: -1.84 | Z13: 39.96 | AA13: 36.73 | AB13: 3.23 | AC13: 38.8 | AF13: 60 | AG13: 60 | AH13: 3.3 | AI13: 3.3 | AJ13: 0
A14: 48226H40040 | B14: A2026100620533560886 | C14: TW-800G 2xFR4_TRx3T_TEC_OSA_Test.vi | D14: Temp | E14: 40 | F14: CH5 | G14: DUT 1 | J14: 74.17 | L14: 347.64 | O14: 1260 | P14: 1271.62 | Q14: 1280 | R14: 0.62 | S14: 0.21 | T14: 54.07 | U14: 1001 | W14: -2.66 | Z14: 39.96 | AA14: 36.73 | AB14: 3.23 | AC14: 38.98 | AF14: 60 | AG14: 60 | AH14: 3.3 | AI14: 3.3 | AJ14: 0
A15: 48226H40040 | B15: A2026100620533560886 | C15: TW-800G 2xFR4_TRx3T_TEC_OSA_Test.vi | D15: Temp | E15: 40 | F15: CH6 | G15: DUT 1 | J15: 74.17 | L15: 347.64 | O15: 1280 | P15: 1291.36 | Q15: 1300 | R15: 0.36 | S15: 0.21 | T15: 55 | U15: 1001 | W15: -0.21 | Z15: 39.96 | AA15: 36.73 | AB15: 3.23 | AC15: 38.59 | AF15: 60 | AG15: 60 | AH15: 3.3 | AI15: 3.3 | AJ15: 0
A16: 48226H40040 | B16: A2026100620533560886 | C16: TW-800G 2xFR4_TRx3T_TEC_OSA_Test.vi | D16: Temp | E16: 40 | F16: CH7 | G16: DUT 1 | J16: 74.17 | L16: 347.64 | O16: 1300 | P16: 1311.8 | Q16: 1320 | R16: 0.8 | S16: 0.21 | T16: 50.04 | U16: 1001 | W16: -1.25 | Z16: 39.96 | AA16: 36.73 | AB16: 3.23 | AC16: 38.74 | AF16: 60 | AG16: 60 | AH16: 3.3 | AI16: 3.3 | AJ16: 0
A17: 48226H40040 | B17: A2026100620533560886 | C17: TW-800G 2xFR4_TRx3T_TEC_OSA_Test.vi | D17: Temp | E17: 40 | F17: CH8 | G17: DUT 1 | J17: 74.17 | L17: 347.64 | O17: 1320 | P17: 1331.42 | Q17: 1340 | R17: 0.42 | S17: 0.2 | T17: 51.65 | U17: 1001 | W17: -1.35 | Z17: 39.96 | AA17: 36.73 | AB17: 3.23 | AC17: 38.8 | AF17: 60 | AG17: 60 | AH17: 3.3 | AI17: 3.3 | AJ17: 0
A18: 48226H40040 | B18: A2026100620533560886 | C18: TW-800G 2xFR4_TRx3T_TEC_OSA_Test.vi | D18: Temp | E18: 40 | F18: CH1 | G18: DUT 1 | J18: 76.28 | L18: 429.35 | O18: 1260 | P18: 1271.66 | Q18: 1280 | R18: 0.66 | S18: 0.21 | T18: 54.98 | U18: 1001 | W18: -1.14 | Z18: 40 | AA18: 36.86 | AB18: 3.14 | AC18: 39.22 | AF18: 70 | AG18: 70 | AH18: 3.3 | AI18: 3.3 | AJ18: 0
A19: 48226H40040 | B19: A2026100620533560886 | C19: TW-800G 2xFR4_TRx3T_TEC_OSA_Test.vi | D19: Temp | E19: 40 | F19: CH2 | G19: DUT 1 | J19: 76.28 | L19: 429.35 | O19: 1280 | P19: 1291.4 | Q19: 1300 | R19: 0.4 | S19: 0.21 | T19: 55.78 | U19: 1001 | W19: 0.4 | Z19: 40 | AA19: 36.86 | AB19: 3.14 | AC19: 38.8 | AF19: 70 | AG19: 70 | AH19: 3.3 | AI19: 3.3 | AJ19: 0
A20: 48226H40040 | B20: A2026100620533560886 | C20: TW-800G 2xFR4_TRx3T_TEC_OSA_Test.vi | D20: Temp | E20: 40 | F20: CH3 | G20: DUT 1 | J20: 76.28 | L20: 429.35 | O20: 1300 | P20: 1311.84 | Q20: 1320 | R20: 0.84 | S20: 0.21 | T20: 50.83 | U20: 1001 | W20: -0.53 | Z20: 40 | AA20: 36.86 | AB20: 3.14 | AC20: 38.98 | AF20: 70 | AG20: 70 | AH20: 3.3 | AI20: 3.3 | AJ20: 0
A21: 48226H40040 | B21: A2026100620533560886 | C21: TW-800G 2xFR4_TRx3T_TEC_OSA_Test.vi | D21: Temp | E21: 40 | F21: CH4 | G21: DUT 1 | J21: 76.28 | L21: 429.35 | O21: 1320 | P21: 1331.44 | Q21: 1340 | R21: 0.44 | S21: 0.2 | T21: 52.4 | U21: 1001 | W21: -0.94 | Z21: 40 | AA21: 36.86 | AB21: 3.14 | AC21: 39.01 | AF21: 70 | AG21: 70 | AH21: 3.3 | AI21: 3.3 | AJ21: 0
... A289: 48226H40040 | B289: A2026100620533560886 | C289: TW-800G 2xFR4_TRx3T_TEC_OSA_Test.vi | D289: Temp | E289: 40 | F289: CH8 | G289: DUT 1 | J289: 75.16 | L289: 3072.73 | O289: 1320 | P289: 1332.54 | Q289: 1340 | R289: 1.54 | S289: 0.24 | T289: 57.64 | U289: 1001 | W289: 5.01 | Z289: 40.01 | AA289: 38.88 | AB289: 1.13 | AC289: 43.87 | AF289: 400 | AG289: 400 | AH289: 3.3 | AI289: 3.3 | AJ289: 0
A290: 48226H40040 | B290: A2026100620533560886 | C290: TW-800G 2xFR4_TRx3T_TEC_OSA_Test.vi | D290: Temp | E290: 35 | F290: CH1 | G290: DUT 1 | I290: 162.77 | J290: 74.7 | L290: 3322.45 | M290: Final test:T157100003549_1 | O290: 1260 | P290: 1271.2 | Q290: 1280 | R290: 0.2 | S290: 0.21 | T290: 53.12 | U290: 1001 | W290: -2.95 | Y290: 35 | Z290: 34.92 | AA290: 31.52 | AB290: 3.4 | AC290: 33.51 | AF290: 50 | AG290: 50 | AH290: 3.3 | AI290: 3.31 | AJ290: -0.01 | AK290: OSA_Test
A291: 48226H40040 | B291: A2026100620533560886 | C291: TW-800G 2xFR4_TRx3T_TEC_OSA_Test.vi | D291: Temp | E291: 35 | F291: CH2 | G291: DUT 1 | I291: 162.77 | J291: 74.7 | L291: 3322.45 | M291: Final test:T157100003549_1 | O291: 1280 | P291: 1290.86 | Q291: 1300 | R291: -0.14 | S291: 0.21 | T291: 54.17 | U291: 1001 | W291: -1.49 | Y291: 35 | Z291: 34.92 | AA291: 31.52 | AB291: 3.4 | AC291: 33.1 | AF291: 50 | AG291: 50 | AH291: 3.3 | AI291: 3.31 | AJ291: -0.01 | AK291: OSA_Test
A292: 48226H40040 | B292: A2026100620533560886 | C292: TW-800G 2xFR4_TRx3T_TEC_OSA_Test.vi | D292: Temp | E292: 35 | F292: CH3 | G292: DUT 1 | I292: 162.77 | J292: 74.7 | L292: 3322.45 | M292: Final test:T157100003549_1 | O292: 1300 | P292: 1311.3 | Q292: 1320 | R292: 0.3 | S292: 0.21 | T292: 49.41 | U292: 1001 | W292: -2.25 | Y292: 35 | Z292: 34.92 | AA292: 31.52 | AB292: 3.4 | AC292: 33.25 | AF292: 50 | AG292: 50 | AH292: 3.3 | AI292: 3.31 | AJ292: -0.01 | AK292: OSA_Test
A293: 48226H40040 | B293: A2026100620533560886 | C293: TW-800G 2xFR4_TRx3T_TEC_OSA_Test.vi | D293: Temp | E293: 35 | F293: CH4 | G293: DUT 1 | I293: 162.77 | J293: 74.7 | L293: 3322.45 | M293: Final test:T157100003549_1 | O293: 1320 | P293: 1330.92 | Q293: 1340 | R293: -0.08 | S293: 0.2 | T293: 51.02 | U293: 1001 | W293: -2.45 | Y293: 35 | Z293: 34.92 | AA293: 31.52 | AB293: 3.4 | AC293: 33.32 | AF293: 50 | AG293: 50 | AH293: 3.3 | AI293: 3.31 | AJ293: -0.01 | AK293: OSA_Test
A294: 48226H40040 | B294: A2026100620533560886 | C294: TW-800G 2xFR4_TRx3T_TEC_OSA_Test.vi | D294: Temp | E294: 35 | F294: CH5 | G294: DUT 1 | I294: 162.77 | J294: 74.7 | L294: 3322.45 | M294: Final test:T157100003549_1 | O294: 1260 | P294: 1271.2 | Q294: 1280 | R294: 0.2 | S294: 0.21 | T294: 53.12 | U294: 1001 | W294: -3.28 | Y294: 35 | Z294: 34.92 | AA294: 31.52 | AB294: 3.4 | AC294: 33.51 | AF294: 50 | AG294: 50 | AH294: 3.3 | AI294: 3.31 | AJ294: -0.01 | AK294: OSA_Test
A295: 48226H40040 | B295: A2026100620533560886 | C295: TW-800G 2xFR4_TRx3T_TEC_OSA_Test.vi | D295: Temp | E295: 35 | F295: CH6 | G295: DUT 1 | I295: 162.77 | J295: 74.7 | L295: 3322.45 | M295: Final test:T157100003549_1 | O295: 1280 | P295: 1290.86 | Q295: 1300 | R295: -0.14 | S295: 0.21 | T295: 54.17 | U295: 1001 | W295: -1.07 | Y295: 35 | Z295: 34.92 | AA295: 31.52 | AB295: 3.4 | AC295: 33.1 | AF295: 50 | AG295: 50 | AH295: 3.3 | AI295: 3.31 | AJ295: -0.01 | AK295: OSA_Test
A296: 48226H40040 | B296: A2026100620533560886 | C296: TW-800G 2xFR4_TRx3T_TEC_OSA_Test.vi | D296: Temp | E296: 35 | F296: CH7 | G296: DUT 1 | I296: 162.77 | J296: 74.7 | L296: 3322.45 | M296: Final test:T157100003549_1 | O296: 1300 | P296: 1311.3 | Q296: 1320 | R296: 0.3 | S296: 0.21 | T296: 49.41 | U296: 1001 | W296: -2.02 | Y296: 35 | Z296: 34.92 | AA296: 31.52 | AB296: 3.4 | AC296: 33.25 | AF296: 50 | AG296: 50 | AH296: 3.3 | AI296: 3.31 | AJ296: -0.01 | AK296: OSA_Test
A297: 48226H40040 | B297: A2026100620533560886 | C297: TW-800G 2xFR4_TRx3T_TEC_OSA_Test.vi | D297: Temp | E297: 35 | F297: CH8 | G297: DUT 1 | I297: 162.77 | J297: 74.7 | L297: 3322.45 | M297: Final test:T157100003549_1 | O297: 1320 | P297: 1330.92 | Q297: 1340 | R297: -0.08 | S297: 0.2 | T297: 51.02 | U297: 1001 | W297: -1.85 | Y297: 35 | Z297: 34.92 | AA297: 31.52 | AB297: 3.4 | AC297: 33.32 | AF297: 50 | AG297: 50 | AH297: 3.3 | AI297: 3.31 | AJ297: -0.01 | AK297: OSA_Test
A298: 48226H40040 | B298: A2026100620533560886 | C298: TW-800G 2xFR4_TRx3T_TEC_OSA_Test.vi | D298: Temp | E298: 35 | F298: CH1 | G298: DUT 1 | J298: 74.03 | L298: 3401.91 | O298: 1260 | P298: 1271.18 | Q298: 1280 | R298: 0.18 | S298: 0.2 | T298: 54.47 | U298: 1001 | W298: -1.48 | Z298: 35.01 | AA298: 31.58 | AB298: 3.43 | AC298: 33.66 | AF298: 60 | AG298: 60 | AH298: 3.3 | AI298: 3.3 | AJ298: 0
A299: 48226H40040 | B299: A2026100620533560886 | C299: TW-800G 2xFR4_TRx3T_TEC_OSA_Test.vi | D299: Temp | E299: 35 | F299: CH2 | G299: DUT 1 | J299: 74.03 | L299: 3401.91 | O299: 1280 | P299: 1290.9 | Q299: 1300 | R299: -0.1 | S299: 0.21 | T299: 55.31 | U299: 1001 | W299: -0.14 | Z299: 35.01 | AA299: 31.58 | AB299: 3.43 | AC299: 33.25 | AF299: 60 | AG299: 60 | AH299: 3.3 | AI299: 3.3 | AJ299: 0
A300: 48226H40040 | B300: A2026100620533560886 | C300: TW-800G 2xFR4_TRx3T_TEC_OSA_Test.vi | D300: Temp | E300: 35 | F300: CH3 | G300: DUT 1 | J300: 74.03 | L300: 3401.91 | O300: 1300 | P300: 1311.36 | Q300: 1320 | R300: 0.36 | S300: 0.21 | T300: 50.45 | U300: 1001 | W300: -1.01 | Z300: 35.01 | AA300: 31.58 | AB300: 3.43 | AC300: 33.37 | AF300: 60 | AG300: 60 | AH300: 3.3 | AI300: 3.3 | AJ300: 0
A301: 48226H40040 | B301: A2026100620533560886 | C301: TW-800G 2xFR4_TRx3T_TEC_OSA_Test.vi | D301: Temp | E301: 35 | F301: CH4 | G301: DUT 1 | J301: 74.03 | L301: 3401.91 | O301: 1320 | P301: 1330.96 | Q301: 1340 | R301: -0.04 | S301: 0.2 | T301: 52.04 | U301: 1001 | W301: -1.3 | Z301: 35.01 | AA301: 31.58 | AB301: 3.43 | AC301: 33.44 | AF301: 60 | AG301: 60 | AH301: 3.3 | AI301: 3.3 | AJ301: 0
A302: 48226H40040 | B302: A2026100620533560886 | C302: TW-800G 2xFR4_TRx3T_TEC_OSA_Test.vi | D302: Temp | E302: 35 | F302: CH5 | G302: DUT 1 | J302: 74.03 | L302: 3401.91 | O302: 1260 | P302: 1271.18 | Q302: 1280 | R302: 0.18 | S302: 0.2 | T302: 54.47 | U302: 1001 | W302: -1.74 | Z302: 35.01 | AA302: 31.58 | AB302: 3.43 | AC302: 33.66 | AF302: 60 | AG302: 60 | AH302: 3.3 | AI302: 3.3 | AJ302: 0
A303: 48226H40040 | B303: A2026100620533560886 | C303: TW-800G 2xFR4_TRx3T_TEC_OSA_Test.vi | D303: Temp | E303: 35 | F303: CH6 | G303: DUT 1 | J303: 74.03 | L303: 3401.91 | O303: 1280 | P303: 1290.9 | Q303: 1300 | R303: -0.1 | S303: 0.21 | T303: 55.31 | U303: 1001 | W303: 0.29 | Z303: 35.01 | AA303: 31.58 | AB303: 3.43 | AC303: 33.25 | AF303: 60 | AG303: 60 | AH303: 3.3 | AI303: 3.3 | AJ303: 0
A304: 48226H40040 | B304: A2026100620533560886 | C304: TW-800G 2xFR4_TRx3T_TEC_OSA_Test.vi | D304: Temp | E304: 35 | F304: CH7 | G304: DUT 1 | J304: 74.03 | L304: 3401.91 | O304: 1300 | P304: 1311.36 | Q304: 1320 | R304: 0.36 | S304: 0.21 | T304: 50.45 | U304: 1001 | W304: -0.67 | Z304: 35.01 | AA304: 31.58 | AB304: 3.43 | AC304: 33.37 | AF304: 60 | AG304: 60 | AH304: 3.3 | AI304: 3.3 | AJ304: 0
A305: 48226H40040 | B305: A2026100620533560886 | C305: TW-800G 2xFR4_TRx3T_TEC_OSA_Test.vi | D305: Temp | E305: 35 | F305: CH8 | G305: DUT 1 | J305: 74.03 | L305: 3401.91 | O305: 1320 | P305: 1330.96 | Q305: 1340 | R305: -0.04 | S305: 0.2 | T305: 52.04 | U305: 1001 | W305: -0.72 | Z305: 35.01 | AA305: 31.58 | AB305: 3.43 | AC305: 33.44 | AF305: 60 | AG305: 60 | AH305: 3.3 | AI305: 3.3 | AJ305: 0
A306: 48226H40040 | B306: A2026100620533560886 | C306: TW-800G 2xFR4_TRx3T_TEC_OSA_Test.vi | D306: Temp | E306: 35 | F306: CH1 | G306: DUT 1 | J306: 76.21 | L306: 3483.56 | O306: 1260 | P306: 1271.2 | Q306: 1280 | R306: 0.2 | S306: 0.2 | T306: 55.35 | U306: 1001 | W306: -0.36 | Z306: 34.99 | AA306: 31.64 | AB306: 3.35 | AC306: 33.75 | AF306: 70 | AG306: 70 | AH306: 3.3 | AI306: 3.3 | AJ306: 0
A307: 48226H40040 | B307: A2026100620533560886 | C307: TW-800G 2xFR4_TRx3T_TEC_OSA_Test.vi | D307: Temp | E307: 35 | F307: CH2 | G307: DUT 1 | J307: 76.21 | L307: 3483.56 | O307: 1280 | P307: 1290.94 | Q307: 1300 | R307: -0.06 | S307: 0.21 | T307: 56.07 | U307: 1001 | W307: 0.83 | Z307: 34.99 | AA307: 31.64 | AB307: 3.35 | AC307: 33.34 | AF307: 70 | AG307: 70 | AH307: 3.3 | AI307: 3.3 | AJ307: 0
...

Sheet Mapping
A1: Wafer | B1: SN | C1: TESTNUMBER | D1: CH (1~4ch) | E1: Temp (-5~75deg C) | F1: Current(mA) | G1: WaveLength(nm) | H1: SMSR(dB) | I1: =RawData!A2&"-Case_Temp" -> 48226H40040-Case_Temp | J1: =RawData!A2&"-DDMI_Temp" -> 48226H40040-DDMI_Temp | K1: ΔWL
A2: M3456E-N | B2: =RawData!A2 -> 48226H40040 | C2: =IF(RawData!$B$2="","",RawData!$B$2) -> A2026100620533560886 | D2: =MOD(INT((ROW()-2)/31),4)+1 -> 1 | E2: =-5+5*INT((ROW()-2)/124) -> -5 | F2: =100+10*MOD(ROW()-2,31) -> 100 | G2: =IF(COUNTIFS(RawData!$E:$E,$E2,RawData!$F:$F,"CH"&$D2,RawData!$AF:$AF,$F2)=0,"",SUMIFS(RawData!$P:$P,RawData!$E:$E,$E2,RawData!$F:$F,"CH"&$D2,RawData!$AF:$AF,$F2)) -> 1267.54 | H2: =IF(COUNTIFS(RawData!$E:$E,$E2,RawData!$F:$F,"CH"&$D2,RawData!$AF:$AF,$F2)=0,"",SUMIFS(RawData!$T:$T,RawData!$E:$E,$E2,RawData!$F:$F,"CH"&$D2,RawData!$AF:$AF,$F2)) -> 58.51 | I2: =IF(COUNTIFS(RawData!$E:$E,$E2,RawData!$F:$F,"CH"&$D2,RawData!$AF:$AF,$F2)=0,"",SUMIFS(RawData!$Z:$Z,RawData!$E:$E,$E2,RawData!$F:$F,"CH"&$D2,RawData!$AF:$AF,$F2)) -> -5.01 | J2: =IF(COUNTIFS(RawData!$E:$E,$E2,RawData!$F:$F,"CH"&$D2,RawData!$AF:$AF,$F2)=0,"",SUMIFS(RawData!$AA:$AA,RawData!$E:$E,$E2,RawData!$F:$F,"CH"&$D2,RawData!$AF:$AF,$F2)) -> -9.18
A3: M3456E-N | B3: =RawData!A3 -> 48226H40040 | C3: =IF(RawData!$B$2="","",RawData!$B$2) -> A2026100620533560886 | D3: =MOD(INT((ROW()-2)/31),4)+1 -> 1 | E3: =-5+5*INT((ROW()-2)/124) -> -5 | F3: =100+10*MOD(ROW()-2,31) -> 110 | G3: =IF(COUNTIFS(RawData!$E:$E,$E3,RawData!$F:$F,"CH"&$D3,RawData!$AF:$AF,$F3)=0,"",SUMIFS(RawData!$P:$P,RawData!$E:$E,$E3,RawData!$F:$F,"CH"&$D3,RawData!$AF:$AF,$F3)) -> 1267.56 | H3: =IF(COUNTIFS(RawData!$E:$E,$E3,RawData!$F:$F,"CH"&$D3,RawData!$AF:$AF,$F3)=0,"",SUMIFS(RawData!$T:$T,RawData!$E:$E,$E3,RawData!$F:$F,"CH"&$D3,RawData!$AF:$AF,$F3)) -> 58.81 | I3: =IF(COUNTIFS(RawData!$E:$E,$E3,RawData!$F:$F,"CH"&$D3,RawData!$AF:$AF,$F3)=0,"",SUMIFS(RawData!$Z:$Z,RawData!$E:$E,$E3,RawData!$F:$F,"CH"&$D3,RawData!$AF:$AF,$F3)) -> -4.96 | J3: =IF(COUNTIFS(RawData!$E:$E,$E3,RawData!$F:$F,"CH"&$D3,RawData!$AF:$AF,$F3)=0,"",SUMIFS(RawData!$AA:$AA,RawData!$E:$E,$E3,RawData!$F:$F,"CH"&$D3,RawData!$AF:$AF,$F3)) -> -9.12 | K3: =G3-G2 -> 0.02
A4: M3456E-N | B4: =RawData!A4 -> 48226H40040 | C4: =IF(RawData!$B$2="","",RawData!$B$2) -> A2026100620533560886 | D4: =MOD(INT((ROW()-2)/31),4)+1 -> 1 | E4: =-5+5*INT((ROW()-2)/124) -> -5 | F4: =100+10*MOD(ROW()-2,31) -> 120 | G4: =IF(COUNTIFS(RawData!$E:$E,$E4,RawData!$F:$F,"CH"&$D4,RawData!$AF:$AF,$F4)=0,"",SUMIFS(RawData!$P:$P,RawData!$E:$E,$E4,RawData!$F:$F,"CH"&$D4,RawData!$AF:$AF,$F4)) -> 1267.58 | H4: =IF(COUNTIFS(RawData!$E:$E,$E4,RawData!$F:$F,"CH"&$D4,RawData!$AF:$AF,$F4)=0,"",SUMIFS(RawData!$T:$T,RawData!$E:$E,$E4,RawData!$F:$F,"CH"&$D4,RawData!$AF:$AF,$F4)) -> 59.07 | I4: =IF(COUNTIFS(RawData!$E:$E,$E4,RawData!$F:$F,"CH"&$D4,RawData!$AF:$AF,$F4)=0,"",SUMIFS(RawData!$Z:$Z,RawData!$E:$E,$E4,RawData!$F:$F,"CH"&$D4,RawData!$AF:$AF,$F4)) -> -4.96 | J4: =IF(COUNTIFS(RawData!$E:$E,$E4,RawData!$F:$F,"CH"&$D4,RawData!$AF:$AF,$F4)=0,"",SUMIFS(RawData!$AA:$AA,RawData!$E:$E,$E4,RawData!$F:$F,"CH"&$D4,RawData!$AF:$AF,$F4)) -> -9.01 | K4: =G4-G3 -> 0.02
A5: M3456E-N | B5: =RawData!A5 -> 48226H40040 | C5: =IF(RawData!$B$2="","",RawData!$B$2) -> A2026100620533560886 | D5: =MOD(INT((ROW()-2)/31),4)+1 -> 1 | E5: =-5+5*INT((ROW()-2)/124) -> -5 | F5: =100+10*MOD(ROW()-2,31) -> 130 | G5: =IF(COUNTIFS(RawData!$E:$E,$E5,RawData!$F:$F,"CH"&$D5,RawData!$AF:$AF,$F5)=0,"",SUMIFS(RawData!$P:$P,RawData!$E:$E,$E5,RawData!$F:$F,"CH"&$D5,RawData!$AF:$AF,$F5)) -> 1267.6 | H5: =IF(COUNTIFS(RawData!$E:$E,$E5,RawData!$F:$F,"CH"&$D5,RawData!$AF:$AF,$F5)=0,"",SUMIFS(RawData!$T:$T,RawData!$E:$E,$E5,RawData!$F:$F,"CH"&$D5,RawData!$AF:$AF,$F5)) -> 59.31 | I5: =IF(COUNTIFS(RawData!$E:$E,$E5,RawData!$F:$F,"CH"&$D5,RawData!$AF:$AF,$F5)=0,"",SUMIFS(RawData!$Z:$Z,RawData!$E:$E,$E5,RawData!$F:$F,"CH"&$D5,RawData!$AF:$AF,$F5)) -> -5.02 | J5: =IF(COUNTIFS(RawData!$E:$E,$E5,RawData!$F:$F,"CH"&$D5,RawData!$AF:$AF,$F5)=0,"",SUMIFS(RawData!$AA:$AA,RawData!$E:$E,$E5,RawData!$F:$F,"CH"&$D5,RawData!$AF:$AF,$F5)) -> -9.04 | K5: =G5-G4 -> 0.02
A6: M3456E-N | B6: =RawData!A6 -> 48226H40040 | C6: =IF(RawData!$B$2="","",RawData!$B$2) -> A2026100620533560886 | D6: =MOD(INT((ROW()-2)/31),4)+1 -> 1 | E6: =-5+5*INT((ROW()-2)/124) -> -5 | F6: =100+10*MOD(ROW()-2,31) -> 140 | G6: =IF(COUNTIFS(RawData!$E:$E,$E6,RawData!$F:$F,"CH"&$D6,RawData!$AF:$AF,$F6)=0,"",SUMIFS(RawData!$P:$P,RawData!$E:$E,$E6,RawData!$F:$F,"CH"&$D6,RawData!$AF:$AF,$F6)) -> 1267.62 | H6: =IF(COUNTIFS(RawData!$E:$E,$E6,RawData!$F:$F,"CH"&$D6,RawData!$AF:$AF,$F6)=0,"",SUMIFS(RawData!$T:$T,RawData!$E:$E,$E6,RawData!$F:$F,"CH"&$D6,RawData!$AF:$AF,$F6)) -> 59.57 | I6: =IF(COUNTIFS(RawData!$E:$E,$E6,RawData!$F:$F,"CH"&$D6,RawData!$AF:$AF,$F6)=0,"",SUMIFS(RawData!$Z:$Z,RawData!$E:$E,$E6,RawData!$F:$F,"CH"&$D6,RawData!$AF:$AF,$F6)) -> -5 | J6: =IF(COUNTIFS(RawData!$E:$E,$E6,RawData!$F:$F,"CH"&$D6,RawData!$AF:$AF,$F6)=0,"",SUMIFS(RawData!$AA:$AA,RawData!$E:$E,$E6,RawData!$F:$F,"CH"&$D6,RawData!$AF:$AF,$F6)) -> -8.89 | K6: =G6-G5 -> 0.02
A7: M3456E-N | B7: =RawData!A7 -> 48226H40040 | C7: =IF(RawData!$B$2="","",RawData!$B$2) -> A2026100620533560886 | D7: =MOD(INT((ROW()-2)/31),4)+1 -> 1 | E7: =-5+5*INT((ROW()-2)/124) -> -5 | F7: =100+10*MOD(ROW()-2,31) -> 150 | G7: =IF(COUNTIFS(RawData!$E:$E,$E7,RawData!$F:$F,"CH"&$D7,RawData!$AF:$AF,$F7)=0,"",SUMIFS(RawData!$P:$P,RawData!$E:$E,$E7,RawData!$F:$F,"CH"&$D7,RawData!$AF:$AF,$F7)) -> 1267.64 | H7: =IF(COUNTIFS(RawData!$E:$E,$E7,RawData!$F:$F,"CH"&$D7,RawData!$AF:$AF,$F7)=0,"",SUMIFS(RawData!$T:$T,RawData!$E:$E,$E7,RawData!$F:$F,"CH"&$D7,RawData!$AF:$AF,$F7)) -> 60.71 | I7: =IF(COUNTIFS(RawData!$E:$E,$E7,RawData!$F:$F,"CH"&$D7,RawData!$AF:$AF,$F7)=0,"",SUMIFS(RawData!$Z:$Z,RawData!$E:$E,$E7,RawData!$F:$F,"CH"&$D7,RawData!$AF:$AF,$F7)) -> -5 | J7: =IF(COUNTIFS(RawData!$E:$E,$E7,RawData!$F:$F,"CH"&$D7,RawData!$AF:$AF,$F7)=0,"",SUMIFS(RawData!$AA:$AA,RawData!$E:$E,$E7,RawData!$F:$F,"CH"&$D7,RawData!$AF:$AF,$F7)) -> -8.89 | K7: =G7-G6 -> 0.02
A8: M3456E-N | B8: =RawData!A8 -> 48226H40040 | C8: =IF(RawData!$B$2="","",RawData!$B$2) -> A2026100620533560886 | D8: =MOD(INT((ROW()-2)/31),4)+1 -> 1 | E8: =-5+5*INT((ROW()-2)/124) -> -5 | F8: =100+10*MOD(ROW()-2,31) -> 160 | G8: =IF(COUNTIFS(RawData!$E:$E,$E8,RawData!$F:$F,"CH"&$D8,RawData!$AF:$AF,$F8)=0,"",SUMIFS(RawData!$P:$P,RawData!$E:$E,$E8,RawData!$F:$F,"CH"&$D8,RawData!$AF:$AF,$F8)) -> 1267.66 | H8: =IF(COUNTIFS(RawData!$E:$E,$E8,RawData!$F:$F,"CH"&$D8,RawData!$AF:$AF,$F8)=0,"",SUMIFS(RawData!$T:$T,RawData!$E:$E,$E8,RawData!$F:$F,"CH"&$D8,RawData!$AF:$AF,$F8)) -> 60.09 | I8: =IF(COUNTIFS(RawData!$E:$E,$E8,RawData!$F:$F,"CH"&$D8,RawData!$AF:$AF,$F8)=0,"",SUMIFS(RawData!$Z:$Z,RawData!$E:$E,$E8,RawData!$F:$F,"CH"&$D8,RawData!$AF:$AF,$F8)) -> -4.99 | J8: =IF(COUNTIFS(RawData!$E:$E,$E8,RawData!$F:$F,"CH"&$D8,RawData!$AF:$AF,$F8)=0,"",SUMIFS(RawData!$AA:$AA,RawData!$E:$E,$E8,RawData!$F:$F,"CH"&$D8,RawData!$AF:$AF,$F8)) -> -8.8 | K8: =G8-G7 -> 0.02
A9: M3456E-N | B9: =RawData!A9 -> 48226H40040 | C9: =IF(RawData!$B$2="","",RawData!$B$2) -> A2026100620533560886 | D9: =MOD(INT((ROW()-2)/31),4)+1 -> 1 | E9: =-5+5*INT((ROW()-2)/124) -> -5 | F9: =100+10*MOD(ROW()-2,31) -> 170 | G9: =IF(COUNTIFS(RawData!$E:$E,$E9,RawData!$F:$F,"CH"&$D9,RawData!$AF:$AF,$F9)=0,"",SUMIFS(RawData!$P:$P,RawData!$E:$E,$E9,RawData!$F:$F,"CH"&$D9,RawData!$AF:$AF,$F9)) -> 1267.68 | H9: =IF(COUNTIFS(RawData!$E:$E,$E9,RawData!$F:$F,"CH"&$D9,RawData!$AF:$AF,$F9)=0,"",SUMIFS(RawData!$T:$T,RawData!$E:$E,$E9,RawData!$F:$F,"CH"&$D9,RawData!$AF:$AF,$F9)) -> 60.21 | I9: =IF(COUNTIFS(RawData!$E:$E,$E9,RawData!$F:$F,"CH"&$D9,RawData!$AF:$AF,$F9)=0,"",SUMIFS(RawData!$Z:$Z,RawData!$E:$E,$E9,RawData!$F:$F,"CH"&$D9,RawData!$AF:$AF,$F9)) -> -4.98 | J9: =IF(COUNTIFS(RawData!$E:$E,$E9,RawData!$F:$F,"CH"&$D9,RawData!$AF:$AF,$F9)=0,"",SUMIFS(RawData!$AA:$AA,RawData!$E:$E,$E9,RawData!$F:$F,"CH"&$D9,RawData!$AF:$AF,$F9)) -> -8.75 | K9: =G9-G8 -> 0.02
A10: M3456E-N | B10: =RawData!A10 -> 48226H40040 | C10: =IF(RawData!$B$2="","",RawData!$B$2) -> A2026100620533560886 | D10: =MOD(INT((ROW()-2)/31),4)+1 -> 1 | E10: =-5+5*INT((ROW()-2)/124) -> -5 | F10: =100+10*MOD(ROW()-2,31) -> 180 | G10: =IF(COUNTIFS(RawData!$E:$E,$E10,RawData!$F:$F,"CH"&$D10,RawData!$AF:$AF,$F10)=0,"",SUMIFS(RawData!$P:$P,RawData!$E:$E,$E10,RawData!$F:$F,"CH"&$D10,RawData!$AF:$AF,$F10)) -> 1267.7 | H10: =IF(COUNTIFS(RawData!$E:$E,$E10,RawData!$F:$F,"CH"&$D10,RawData!$AF:$AF,$F10)=0,"",SUMIFS(RawData!$T:$T,RawData!$E:$E,$E10,RawData!$F:$F,"CH"&$D10,RawData!$AF:$AF,$F10)) -> 61.21 | I10: =IF(COUNTIFS(RawData!$E:$E,$E10,RawData!$F:$F,"CH"&$D10,RawData!$AF:$AF,$F10)=0,"",SUMIFS(RawData!$Z:$Z,RawData!$E:$E,$E10,RawData!$F:$F,"CH"&$D10,RawData!$AF:$AF,$F10)) -> -4.98 | J10: =IF(COUNTIFS(RawData!$E:$E,$E10,RawData!$F:$F,"CH"&$D10,RawData!$AF:$AF,$F10)=0,"",SUMIFS(RawData!$AA:$AA,RawData!$E:$E,$E10,RawData!$F:$F,"CH"&$D10,RawData!$AF:$AF,$F10)) -> -8.66 | K10: =G10-G9 -> 0.02
A11: M3456E-N | B11: =RawData!A11 -> 48226H40040 | C11: =IF(RawData!$B$2="","",RawData!$B$2) -> A2026100620533560886 | D11: =MOD(INT((ROW()-2)/31),4)+1 -> 1 | E11: =-5+5*INT((ROW()-2)/124) -> -5 | F11: =100+10*MOD(ROW()-2,31) -> 190 | G11: =IF(COUNTIFS(RawData!$E:$E,$E11,RawData!$F:$F,"CH"&$D11,RawData!$AF:$AF,$F11)=0,"",SUMIFS(RawData!$P:$P,RawData!$E:$E,$E11,RawData!$F:$F,"CH"&$D11,RawData!$AF:$AF,$F11)) -> 1267.72 | H11: =IF(COUNTIFS(RawData!$E:$E,$E11,RawData!$F:$F,"CH"&$D11,RawData!$AF:$AF,$F11)=0,"",SUMIFS(RawData!$T:$T,RawData!$E:$E,$E11,RawData!$F:$F,"CH"&$D11,RawData!$AF:$AF,$F11)) -> 61.37 | I11: =IF(COUNTIFS(RawData!$E:$E,$E11,RawData!$F:$F,"CH"&$D11,RawData!$AF:$AF,$F11)=0,"",SUMIFS(RawData!$Z:$Z,RawData!$E:$E,$E11,RawData!$F:$F,"CH"&$D11,RawData!$AF:$AF,$F11)) -> -5 | J11: =IF(COUNTIFS(RawData!$E:$E,$E11,RawData!$F:$F,"CH"&$D11,RawData!$AF:$AF,$F11)=0,"",SUMIFS(RawData!$AA:$AA,RawData!$E:$E,$E11,RawData!$F:$F,"CH"&$D11,RawData!$AF:$AF,$F11)) -> -8.66 | K11: =G11-G10 -> 0.02
A12: M3456E-N | B12: =RawData!A12 -> 48226H40040 | C12: =IF(RawData!$B$2="","",RawData!$B$2) -> A2026100620533560886 | D12: =MOD(INT((ROW()-2)/31),4)+1 -> 1 | E12: =-5+5*INT((ROW()-2)/124) -> -5 | F12: =100+10*MOD(ROW()-2,31) -> 200 | G12: =IF(COUNTIFS(RawData!$E:$E,$E12,RawData!$F:$F,"CH"&$D12,RawData!$AF:$AF,$F12)=0,"",SUMIFS(RawData!$P:$P,RawData!$E:$E,$E12,RawData!$F:$F,"CH"&$D12,RawData!$AF:$AF,$F12)) -> 1267.74 | H12: =IF(COUNTIFS(RawData!$E:$E,$E12,RawData!$F:$F,"CH"&$D12,RawData!$AF:$AF,$F12)=0,"",SUMIFS(RawData!$T:$T,RawData!$E:$E,$E12,RawData!$F:$F,"CH"&$D12,RawData!$AF:$AF,$F12)) -> 61.56 | I12: =IF(COUNTIFS(RawData!$E:$E,$E12,RawData!$F:$F,"CH"&$D12,RawData!$AF:$AF,$F12)=0,"",SUMIFS(RawData!$Z:$Z,RawData!$E:$E,$E12,RawData!$F:$F,"CH"&$D12,RawData!$AF:$AF,$F12)) -> -4.97 | J12: =IF(COUNTIFS(RawData!$E:$E,$E12,RawData!$F:$F,"CH"&$D12,RawData!$AF:$AF,$F12)=0,"",SUMIFS(RawData!$AA:$AA,RawData!$E:$E,$E12,RawData!$F:$F,"CH"&$D12,RawData!$AF:$AF,$F12)) -> -8.54 | K12: =G12-G11 -> 0.02
A13: M3456E-N | B13: =RawData!A13 -> 48226H40040 | C13: =IF(RawData!$B$2="","",RawData!$B$2) -> A2026100620533560886 | D13: =MOD(INT((ROW()-2)/31),4)+1 -> 1 | E13: =-5+5*INT((ROW()-2)/124) -> -5 | F13: =100+10*MOD(ROW()-2,31) -> 210 | G13: =IF(COUNTIFS(RawData!$E:$E,$E13,RawData!$F:$F,"CH"&$D13,RawData!$AF:$AF,$F13)=0,"",SUMIFS(RawData!$P:$P,RawData!$E:$E,$E13,RawData!$F:$F,"CH"&$D13,RawData!$AF:$AF,$F13)) -> 1267.78 | H13: =IF(COUNTIFS(RawData!$E:$E,$E13,RawData!$F:$F,"CH"&$D13,RawData!$AF:$AF,$F13)=0,"",SUMIFS(RawData!$T:$T,RawData!$E:$E,$E13,RawData!$F:$F,"CH"&$D13,RawData!$AF:$AF,$F13)) -> 61.58 | I13: =IF(COUNTIFS(RawData!$E:$E,$E13,RawData!$F:$F,"CH"&$D13,RawData!$AF:$AF,$F13)=0,"",SUMIFS(RawData!$Z:$Z,RawData!$E:$E,$E13,RawData!$F:$F,"CH"&$D13,RawData!$AF:$AF,$F13)) -> -5.02 | J13: =IF(COUNTIFS(RawData!$E:$E,$E13,RawData!$F:$F,"CH"&$D13,RawData!$AF:$AF,$F13)=0,"",SUMIFS(RawData!$AA:$AA,RawData!$E:$E,$E13,RawData!$F:$F,"CH"&$D13,RawData!$AF:$AF,$F13)) -> -8.6 | K13: =G13-G12 -> 0.04
A14: M3456E-N | B14: =RawData!A14 -> 48226H40040 | C14: =IF(RawData!$B$2="","",RawData!$B$2) -> A2026100620533560886 | D14: =MOD(INT((ROW()-2)/31),4)+1 -> 1 | E14: =-5+5*INT((ROW()-2)/124) -> -5 | F14: =100+10*MOD(ROW()-2,31) -> 220 | G14: =IF(COUNTIFS(RawData!$E:$E,$E14,RawData!$F:$F,"CH"&$D14,RawData!$AF:$AF,$F14)=0,"",SUMIFS(RawData!$P:$P,RawData!$E:$E,$E14,RawData!$F:$F,"CH"&$D14,RawData!$AF:$AF,$F14)) -> 1267.78 | H14: =IF(COUNTIFS(RawData!$E:$E,$E14,RawData!$F:$F,"CH"&$D14,RawData!$AF:$AF,$F14)=0,"",SUMIFS(RawData!$T:$T,RawData!$E:$E,$E14,RawData!$F:$F,"CH"&$D14,RawData!$AF:$AF,$F14)) -> 61.8 | I14: =IF(COUNTIFS(RawData!$E:$E,$E14,RawData!$F:$F,"CH"&$D14,RawData!$AF:$AF,$F14)=0,"",SUMIFS(RawData!$Z:$Z,RawData!$E:$E,$E14,RawData!$F:$F,"CH"&$D14,RawData!$AF:$AF,$F14)) -> -4.99 | J14: =IF(COUNTIFS(RawData!$E:$E,$E14,RawData!$F:$F,"CH"&$D14,RawData!$AF:$AF,$F14)=0,"",SUMIFS(RawData!$AA:$AA,RawData!$E:$E,$E14,RawData!$F:$F,"CH"&$D14,RawData!$AF:$AF,$F14)) -> -8.45 | K14: =G14-G13 -> 0
... A2109: M3459C-N | B2109: =RawData!A2109 -> 48226H40040 | C2109: =IF(RawData!$B$2="","",RawData!$B$2) -> A2026100620533560886 | D2109: =MOD(INT((ROW()-2)/31),4)+1 -> 4 | E2109: =-5+5*INT((ROW()-2)/124) -> 75 | F2109: =100+10*MOD(ROW()-2,31) -> 400 | G2109: =IF(COUNTIFS(RawData!$E:$E,$E2109,RawData!$F:$F,"CH"&$D2109,RawData!$AF:$AF,$F2109)=0,"",SUMIFS(RawData!$P:$P,RawData!$E:$E,$E2109,RawData!$F:$F,"CH"&$D2109,RawData!$AF:$AF,$F2109)) -> 1336.28 | H2109: =IF(COUNTIFS(RawData!$E:$E,$E2109,RawData!$F:$F,"CH"&$D2109,RawData!$AF:$AF,$F2109)=0,"",SUMIFS(RawData!$T:$T,RawData!$E:$E,$E2109,RawData!$F:$F,"CH"&$D2109,RawData!$AF:$AF,$F2109)) -> 56.43 | I2109: =IF(COUNTIFS(RawData!$E:$E,$E2109,RawData!$F:$F,"CH"&$D2109,RawData!$AF:$AF,$F2109)=0,"",SUMIFS(RawData!$Z:$Z,RawData!$E:$E,$E2109,RawData!$F:$F,"CH"&$D2109,RawData!$AF:$AF,$F2109)) -> 74.99 | J2109: =IF(COUNTIFS(RawData!$E:$E,$E2109,RawData!$F:$F,"CH"&$D2109,RawData!$AF:$AF,$F2109)=0,"",SUMIFS(RawData!$AA:$AA,RawData!$E:$E,$E2109,RawData!$F:$F,"CH"&$D2109,RawData!$AF:$AF,$F2109)) -> 78.45 | K2109: =G2109-G2108 -> 0.04
